Workbook

Sheet MULAI
A1: CARA PAKAI FILE INI
A3: 1. TES ADD-IN: ketik di sel D3 sheet ini: =TR(".JKSE","TR.PriceClose") lalu Enter. Harus keluar angka (harga IHSG).
A4: Kalau #NAME?, coba =RDP.Data(".JKSE","TR.PriceClose"). Kalau itu yang jalan: Ctrl+H, ganti semua '=TR(' menjadi '=RDP.Data(' (Within: Workbook).
A6: 2. CARA REFRESH SATU SHEET: klik tab sheet -> menu Formulas -> Calculate Sheet (atau Fn+Shift+F9).
A7: JANGAN klik 'Calculate Now' (menarik semua sheet sekaligus, Excel bisa macet). Tunggu sampai sel berhenti loading, lalu Ctrl+S.
A9: 3. (Opsional, 20 menit) Sheet config: isi RIC/field yang kosong; kalau sebuah deret gagal, coba isian kolom 'Alternatif jika kosong'.
A10: Kalau tidak ketemu, biarkan kosong - aman, nanti dilewati.
A12: 4. REFRESH SHEET SESUAI URUTAN INI (Save setiap selesai satu sheet):
A13: 1. tickers <- P1, wajib untuk brief
A14: 2. bench <- P1, wajib untuk brief
A15: 3. tr_pct_2025 <- P1, wajib untuk brief
A16: 4. px_last_2025 <- P1, wajib untuk brief
... A40: Ada error yang aneh? Screenshot dan kirim ke Claude.

Sheet config
A1: Mulai deret pasar | B1: 2010-01-01
A2: Akhir | B2: 2026-12-31
A3: RIC MSCI Indonesia | B3: .dMIID00000NUS
A4: RIC FTSE Indonesia (isi dulu)
A5: Mulai data statis historis | B5: 2015-01-01
A7: Parameter deret pasar harian | B7: ="SDate="&$B$1&" EDate="&$B$2&" Frq=D CH=Fd RH=IN"
A8: Parameter statis kuartalan | B8: ="SDate="&$B$5&" EDate="&$B$2&" Frq=CQ CH=Fd RH=IN"
A10: Periode saham 2025 | B10: ="SDate=2025-01-01 EDate=2026-12-31 Frq=D CH=Fd RH=IN"
A11: Periode saham 2020 | B11: ="SDate=2020-01-01 EDate=2024-12-31 Frq=D CH=Fd RH=IN"
A12: Periode saham 2015 | B12: ="SDate=2015-01-01 EDate=2019-12-31 Frq=D CH=Fd RH=IN"
A19: Deret pasar | B19: RIC (isi/cek) | C19: Field (ganti bila kosong) | D19: Alternatif jika kosong
A20: JCI | B20: .JKSE | C20: TR.PriceClose
A21: MXEF | B21: .dMIEF00000NUS | C21: TR.PriceClose | D21: RIC .dMIEF00000PUS
A22: SBN10Y | B22: ID10YT=RR | C22: TR.BidYield | D22: field TR.MidYield
A23: USDIDR | B23: IDR= | C23: TR.MidPrice | D23: field TR.BidPrice
A24: MXID | B24: .dMIID00000NUS | C24: TR.PriceClose | D24: RIC .dMIID00000PUS / .dMIID00000PID
A25: CDS5Y | C25: TR.MidSpread | D25: cari 'Indonesia CDS 5Y'; field TR.BidSpread / TR.PriceClose
A26: VIX | B26: .VIX | C26: TR.PriceClose
A27: COAL | C27: TR.PriceClose | D27: cari 'Newcastle coal futures'
A28: CPO | C28: TR.PriceClose | D28: cari 'Crude palm oil futures Bursa Malaysia'
A29: NICKEL | C29: TR.PriceClose | D29: cari 'LME nickel 3 month'
A30: EQ_TH | B30: .SETI | C30: TR.PriceClose
A31: EQ_MY | B31: .KLSE | C31: TR.PriceClose
A32: EQ_PH | B32: .PSI | C32: TR.PriceClose
A33: EQ_IN | B33: .NSEI | C33: TR.PriceClose
A34: EQ_BR | B34: .BVSP | C34: TR.PriceClose
A35: EQ_MX | B35: .MXX | C35: TR.PriceClose
A36: EQ_TR | B36: .XU100 | C36: TR.PriceClose
A37: EQ_ZA | B37: .JTOPI | C37: TR.PriceClose
A38: EQ_KR | B38: .KS11 | C38: TR.PriceClose
A39: EQ_TW | B39: .TWII | C39: TR.PriceClose
A40: EQ_VN | B40: .VNI | C40: TR.PriceClose
A41: EQ_PL | B41: .WIG20 | C41: TR.PriceClose
A42: EQ_CL | B42: .SPIPSA | C42: TR.PriceClose
A43: Y10_TH | B43: TH10YT=RR | C43: TR.BidYield | D43: field TR.MidYield
A44: Y10_MY | B44: MY10YT=RR | C44: TR.BidYield | D44: field TR.MidYield
A45: Y10_PH | B45: PH10YT=RR | C45: TR.BidYield | D45: field TR.MidYield
A46: Y10_IN | B46: IN10YT=RR | C46: TR.BidYield | D46: field TR.MidYield
A47: Y10_BR | B47: BR10YT=RR | C47: TR.BidYield | D47: field TR.MidYield
A48: Y10_MX | B48: MX10YT=RR | C48: TR.BidYield | D48: field TR.MidYield
...

Sheet tickers
A1: =TR(config!$B$20,"TR.IndexConstituentRIC","CH=Fd RH=IN")

Sheet bench
A1: JCI | E1: MXEF | I1: SBN10Y | M1: USDIDR | Q1: MXID | U1: CDS5Y | Y1: VIX | AC1: COAL | AG1: CPO | AK1: NICKEL | AO1: EQ_TH | AS1: EQ_MY | AW1: EQ_PH | BA1: EQ_IN | BE1: EQ_BR | BI1: EQ_MX | BM1: EQ_TR | BQ1: EQ_ZA | BU1: EQ_KR | BY1: EQ_TW | CC1: EQ_VN | CG1: EQ_PL | CK1: EQ_CL | CO1: Y10_TH | CS1: Y10_MY | CW1: Y10_PH | DA1: Y10_IN | DE1: Y10_BR | DI1: Y10_MX | DM1: Y10_TR | DQ1: Y10_ZA | DU1: Y10_KR | DY1: Y10_TW | EC1: Y10_VN | EG1: Y10_PL | EK1: Y10_CL | EO1: FX_TH | ES1: FX_MY | EW1: FX_PH | FA1: FX_IN | FE1: FX_BR | FI1: FX_MX | FM1: FX_TR | FQ1: FX_ZA | FU1: FX_KR | FY1: FX_TW | GC1: FX_VN | GG1: FX_PL | GK1: FX_CL | GO1: BANK_ID | GS1: BANK_EM | GW1: BANK_TH | HA1: BANK_MY | HE1: BANK_PH | HI1: BANK_IN | HM1: BANK_BR | HQ1: BANK_MX | HU1: BANK_TR | HY1: BANK_ZA | IC1: BANK_KR | IG1: BANK_TW | IK1: BANK_VN | IO1: BANK_PL | IS1: BANK_CL | IW1: ETF_EIDO_AUM | JA1: ETF_EEM_AUM | JE1: ETF_VWO_AUM | JI1: ETF_EMLC_AUM | JM1: GBIEM_ID_BOBOT
A2: =TR(config!$B$20,config!$C$20&".date;"&config!$C$20,config!$B$7) | E2: =TR(config!$B$21,config!$C$21&".date;"&config!$C$21,config!$B$7) | I2: =TR(config!$B$22,config!$C$22&".date;"&config!$C$22,config!$B$7) | M2: =TR(config!$B$23,config!$C$23&".date;"&config!$C$23,config!$B$7) | Q2: =TR(config!$B$24,config!$C$24&".date;"&config!$C$24,config!$B$7) | U2: =TR(config!$B$25,config!$C$25&".date;"&config!$C$25,config!$B$7) | Y2: =TR(config!$B$26,config!$C$26&".date;"&config!$C$26,config!$B$7) | AC2: =TR(config!$B$27,config!$C$27&".date;"&config!$C$27,config!$B$7) | AG2: =TR(config!$B$28,config!$C$28&".date;"&config!$C$28,config!$B$7) | AK2: =TR(config!$B$29,config!$C$29&".date;"&config!$C$29,config!$B$7) | AO2: =TR(config!$B$30,config!$C$30&".date;"&config!$C$30,config!$B$7) | AS2: =TR(config!$B$31,config!$C$31&".date;"&config!$C$31,config!$B$7) | AW2: =TR(config!$B$32,config!$C$32&".date;"&config!$C$32,config!$B$7) | BA2: =TR(config!$B$33,config!$C$33&".date;"&config!$C$33,config!$B$7) | BE2: =TR(config!$B$34,config!$C$34&".date;"&config!$C$34,config!$B$7) | BI2: =TR(config!$B$35,config!$C$35&".date;"&config!$C$35,config!$B$7) | BM2: =TR(config!$B$36,config!$C$36&".date;"&config!$C$36,config!$B$7) | BQ2: =TR(config!$B$37,config!$C$37&".date;"&config!$C$37,config!$B$7) | BU2: =TR(config!$B$38,config!$C$38&".date;"&config!$C$38,config!$B$7) | BY2: =TR(config!$B$39,config!$C$39&".date;"&config!$C$39,config!$B$7) | CC2: =TR(config!$B$40,config!$C$40&".date;"&config!$C$40,config!$B$7) | CG2: =TR(config!$B$41,config!$C$41&".date;"&config!$C$41,config!$B$7) | CK2: =TR(config!$B$42,config!$C$42&".date;"&config!$C$42,config!$B$7) | CO2: =TR(config!$B$43,config!$C$43&".date;"&config!$C$43,config!$B$7) | CS2: =TR(config!$B$44,config!$C$44&".date;"&config!$C$44,config!$B$7) | CW2: =TR(config!$B$45,config!$C$45&".date;"&config!$C$45,config!$B$7) | DA2: =TR(config!$B$46,config!$C$46&".date;"&config!$C$46,config!$B$7) | DE2: =TR(config!$B$47,config!$C$47&".date;"&config!$C$47,config!$B$7) | DI2: =TR(config!$B$48,config!$C$48&".date;"&config!$C$48,config!$B$7) | DM2: =TR(config!$B$49,config!$C$49&".date;"&config!$C$49,config!$B$7) | DQ2: =TR(config!$B$50,config!$C$50&".date;"&config!$C$50,config!$B$7) | DU2: =TR(config!$B$51,config!$C$51&".date;"&config!$C$51,config!$B$7) | DY2: =TR(config!$B$52,config!$C$52&".date;"&config!$C$52,config!$B$7) | EC2: =TR(config!$B$53,config!$C$53&".date;"&config!$C$53,config!$B$7) | EG2: =TR(config!$B$54,config!$C$54&".date;"&config!$C$54,config!$B$7) | EK2: =TR(config!$B$55,config!$C$55&".date;"&config!$C$55,config!$B$7) | EO2: =TR(config!$B$56,config!$C$56&".date;"&config!$C$56,config!$B$7) | ES2: =TR(config!$B$57,config!$C$57&".date;"&config!$C$57,config!$B$7) | EW2: =TR(config!$B$58,config!$C$58&".date;"&config!$C$58,config!$B$7) | FA2: =TR(config!$B$59,config!$C$59&".date;"&config!$C$59,config!$B$7) | FE2: =TR(config!$B$60,config!$C$60&".date;"&config!$C$60,config!$B$7) | FI2: =TR(config!$B$61,config!$C$61&".date;"&config!$C$61,config!$B$7) | FM2: =TR(config!$B$62,config!$C$62&".date;"&config!$C$62,config!$B$7) | FQ2: =TR(config!$B$63,config!$C$63&".date;"&config!$C$63,config!$B$7) | FU2: =TR(config!$B$64,config!$C$64&".date;"&config!$C$64,config!$B$7) | FY2: =TR(config!$B$65,config!$C$65&".date;"&config!$C$65,config!$B$7) | GC2: =TR(config!$B$66,config!$C$66&".date;"&config!$C$66,config!$B$7) | GG2: =TR(config!$B$67,config!$C$67&".date;"&config!$C$67,config!$B$7) | GK2: =TR(config!$B$68,config!$C$68&".date;"&config!$C$68,config!$B$7) | GO2: =TR(config!$B$69,config!$C$69&".date;"&config!$C$69,config!$B$7) | GS2: =TR(config!$B$70,config!$C$70&".date;"&config!$C$70,config!$B$7) | GW2: =TR(config!$B$71,config!$C$71&".date;"&config!$C$71,config!$B$7) | HA2: =TR(config!$B$72,config!$C$72&".date;"&config!$C$72,config!$B$7) | HE2: =TR(config!$B$73,config!$C$73&".date;"&config!$C$73,config!$B$7) | HI2: =TR(config!$B$74,config!$C$74&".date;"&config!$C$74,config!$B$7) | HM2: =TR(config!$B$75,config!$C$75&".date;"&config!$C$75,config!$B$7) | HQ2: =TR(config!$B$76,config!$C$76&".date;"&config!$C$76,config!$B$7) | HU2: =TR(config!$B$77,config!$C$77&".date;"&config!$C$77,config!$B$7) | HY2: =TR(config!$B$78,config!$C$78&".date;"&config!$C$78,config!$B$7) | IC2: =TR(config!$B$79,config!$C$79&".date;"&config!$C$79,config!$B$7) | IG2: =TR(config!$B$80,config!$C$80&".date;"&config!$C$80,config!$B$7) | IK2: =TR(config!$B$81,config!$C$81&".date;"&config!$C$81,config!$B$7) | IO2: =TR(config!$B$82,config!$C$82&".date;"&config!$C$82,config!$B$7) | IS2: =TR(config!$B$83,config!$C$83&".date;"&config!$C$83,config!$B$7) | IW2: =TR(config!$B$84,config!$C$84&".date;"&config!$C$84,config!$B$7) | JA2: =TR(config!$B$85,config!$C$85&".date;"&config!$C$85,config!$B$7) | JE2: =TR(config!$B$86,config!$C$86&".date;"&config!$C$86,config!$B$7) | JI2: =TR(config!$B$87,config!$C$87&".date;"&config!$C$87,config!$B$7) | JM2: =TR(config!$B$88,config!$C$88&".date;"&config!$C$88,config!$B$7)

Sheet tr_pct_2025
A1: tickers B2:B26 | E1: tickers B27:B51 | I1: tickers B52:B76 | M1: tickers B77:B101 | Q1: tickers B102:B126 | U1: tickers B127:B151 | Y1: tickers B152:B176 | AC1: tickers B177:B201 | AG1: tickers B202:B226 | AK1: tickers B227:B251 | AO1: tickers B252:B276 | AS1: tickers B277:B301 | AW1: tickers B302:B326 | BA1: tickers B327:B351 | BE1: tickers B352:B376 | BI1: tickers B377:B401 | BM1: tickers B402:B426 | BQ1: tickers B427:B451 | BU1: tickers B452:B476 | BY1: tickers B477:B501 | CC1: tickers B502:B526 | CG1: tickers B527:B551 | CK1: tickers B552:B576 | CO1: tickers B577:B601 | CS1: tickers B602:B626 | CW1: tickers B627:B651 | DA1: tickers B652:B676 | DE1: tickers B677:B701 | DI1: tickers B702:B726 | DM1: tickers B727:B751 | DQ1: tickers B752:B776 | DU1: tickers B777:B801 | DY1: tickers B802:B826 | EC1: tickers B827:B851 | EG1: tickers B852:B876 | EK1: tickers B877:B901 | EO1: tickers B902:B926 | ES1: tickers B927:B951 | EW1: tickers B952:B976 | FA1: tickers B977:B1001 | FE1: tickers B1002:B1026 | FI1: tickers B1027:B1051 | FM1: tickers B1052:B1076 | FQ1: tickers B1077:B1101 | FU1: tickers B1102:B1126 | FY1: tickers B1127:B1151 | GC1: tickers B1152:B1176 | GG1: tickers B1177:B1201 | GK1: tickers B1202:B1226 | GO1: tickers B1227:B1251 | GS1: tickers B1252:B1276 | GW1: tickers B1277:B1301 | HA1: tickers B1302:B1326 | HE1: tickers B1327:B1351 | HI1: tickers B1352:B1376 | HM1: tickers B1377:B1401 | HQ1: tickers B1402:B1426 | HU1: tickers B1427:B1451 | HY1: tickers B1452:B1476 | IC1: tickers B1477:B1501
A2: =TR(tickers!$B$2:$B$26,"TR.TotalReturn.date;TR.TotalReturn",config!$B$10) | E2: =TR(tickers!$B$27:$B$51,"TR.TotalReturn.date;TR.TotalReturn",config!$B$10) | I2: =TR(tickers!$B$52:$B$76,"TR.TotalReturn.date;TR.TotalReturn",config!$B$10) | M2: =TR(tickers!$B$77:$B$101,"TR.TotalReturn.date;TR.TotalReturn",config!$B$10) | Q2: =TR(tickers!$B$102:$B$126,"TR.TotalReturn.date;TR.TotalReturn",config!$B$10) | U2: =TR(tickers!$B$127:$B$151,"TR.TotalReturn.date;TR.TotalReturn",config!$B$10) | Y2: =TR(tickers!$B$152:$B$176,"TR.TotalReturn.date;TR.TotalReturn",config!$B$10) | AC2: =TR(tickers!$B$177:$B$201,"TR.TotalReturn.date;TR.TotalReturn",config!$B$10) | AG2: =TR(tickers!$B$202:$B$226,"TR.TotalReturn.date;TR.TotalReturn",config!$B$10) | AK2: =TR(tickers!$B$227:$B$251,"TR.TotalReturn.date;TR.TotalReturn",config!$B$10) | AO2: =TR(tickers!$B$252:$B$276,"TR.TotalReturn.date;TR.TotalReturn",config!$B$10) | AS2: =TR(tickers!$B$277:$B$301,"TR.TotalReturn.date;TR.TotalReturn",config!$B$10) | AW2: =TR(tickers!$B$302:$B$326,"TR.TotalReturn.date;TR.TotalReturn",config!$B$10) | BA2: =TR(tickers!$B$327:$B$351,"TR.TotalReturn.date;TR.TotalReturn",config!$B$10) | BE2: =TR(tickers!$B$352:$B$376,"TR.TotalReturn.date;TR.TotalReturn",config!$B$10) | BI2: =TR(tickers!$B$377:$B$401,"TR.TotalReturn.date;TR.TotalReturn",config!$B$10) | BM2: =TR(tickers!$B$402:$B$426,"TR.TotalReturn.date;TR.TotalReturn",config!$B$10) | BQ2: =TR(tickers!$B$427:$B$451,"TR.TotalReturn.date;TR.TotalReturn",config!$B$10) | BU2: =TR(tickers!$B$452:$B$476,"TR.TotalReturn.date;TR.TotalReturn",config!$B$10) | BY2: =TR(tickers!$B$477:$B$501,"TR.TotalReturn.date;TR.TotalReturn",config!$B$10) | CC2: =TR(tickers!$B$502:$B$526,"TR.TotalReturn.date;TR.TotalReturn",config!$B$10) | CG2: =TR(tickers!$B$527:$B$551,"TR.TotalReturn.date;TR.TotalReturn",config!$B$10) | CK2: =TR(tickers!$B$552:$B$576,"TR.TotalReturn.date;TR.TotalReturn",config!$B$10) | CO2: =TR(tickers!$B$577:$B$601,"TR.TotalReturn.date;TR.TotalReturn",config!$B$10) | CS2: =TR(tickers!$B$602:$B$626,"TR.TotalReturn.date;TR.TotalReturn",config!$B$10) | CW2: =TR(tickers!$B$627:$B$651,"TR.TotalReturn.date;TR.TotalReturn",config!$B$10) | DA2: =TR(tickers!$B$652:$B$676,"TR.TotalReturn.date;TR.TotalReturn",config!$B$10) | DE2: =TR(tickers!$B$677:$B$701,"TR.TotalReturn.date;TR.TotalReturn",config!$B$10) | DI2: =TR(tickers!$B$702:$B$726,"TR.TotalReturn.date;TR.TotalReturn",config!$B$10) | DM2: =TR(tickers!$B$727:$B$751,"TR.TotalReturn.date;TR.TotalReturn",config!$B$10) | DQ2: =TR(tickers!$B$752:$B$776,"TR.TotalReturn.date;TR.TotalReturn",config!$B$10) | DU2: =TR(tickers!$B$777:$B$801,"TR.TotalReturn.date;TR.TotalReturn",config!$B$10) | DY2: =TR(tickers!$B$802:$B$826,"TR.TotalReturn.date;TR.TotalReturn",config!$B$10) | EC2: =TR(tickers!$B$827:$B$851,"TR.TotalReturn.date;TR.TotalReturn",config!$B$10) | EG2: =TR(tickers!$B$852:$B$876,"TR.TotalReturn.date;TR.TotalReturn",config!$B$10) | EK2: =TR(tickers!$B$877:$B$901,"TR.TotalReturn.date;TR.TotalReturn",config!$B$10) | EO2: =TR(tickers!$B$902:$B$926,"TR.TotalReturn.date;TR.TotalReturn",config!$B$10) | ES2: =TR(tickers!$B$927:$B$951,"TR.TotalReturn.date;TR.TotalReturn",config!$B$10) | EW2: =TR(tickers!$B$952:$B$976,"TR.TotalReturn.date;TR.TotalReturn",config!$B$10) | FA2: =TR(tickers!$B$977:$B$1001,"TR.TotalReturn.date;TR.TotalReturn",config!$B$10) | FE2: =TR(tickers!$B$1002:$B$1026,"TR.TotalReturn.date;TR.TotalReturn",config!$B$10) | FI2: =TR(tickers!$B$1027:$B$1051,"TR.TotalReturn.date;TR.TotalReturn",config!$B$10) | FM2: =TR(tickers!$B$1052:$B$1076,"TR.TotalReturn.date;TR.TotalReturn",config!$B$10) | FQ2: =TR(tickers!$B$1077:$B$1101,"TR.TotalReturn.date;TR.TotalReturn",config!$B$10) | FU2: =TR(tickers!$B$1102:$B$1126,"TR.TotalReturn.date;TR.TotalReturn",config!$B$10) | FY2: =TR(tickers!$B$1127:$B$1151,"TR.TotalReturn.date;TR.TotalReturn",config!$B$10) | GC2: =TR(tickers!$B$1152:$B$1176,"TR.TotalReturn.date;TR.TotalReturn",config!$B$10) | GG2: =TR(tickers!$B$1177:$B$1201,"TR.TotalReturn.date;TR.TotalReturn",config!$B$10) | GK2: =TR(tickers!$B$1202:$B$1226,"TR.TotalReturn.date;TR.TotalReturn",config!$B$10) | GO2: =TR(tickers!$B$1227:$B$1251,"TR.TotalReturn.date;TR.TotalReturn",config!$B$10) | GS2: =TR(tickers!$B$1252:$B$1276,"TR.TotalReturn.date;TR.TotalReturn",config!$B$10) | GW2: =TR(tickers!$B$1277:$B$1301,"TR.TotalReturn.date;TR.TotalReturn",config!$B$10) | HA2: =TR(tickers!$B$1302:$B$1326,"TR.TotalReturn.date;TR.TotalReturn",config!$B$10) | HE2: =TR(tickers!$B$1327:$B$1351,"TR.TotalReturn.date;TR.TotalReturn",config!$B$10) | HI2: =TR(tickers!$B$1352:$B$1376,"TR.TotalReturn.date;TR.TotalReturn",config!$B$10) | HM2: =TR(tickers!$B$1377:$B$1401,"TR.TotalReturn.date;TR.TotalReturn",config!$B$10) | HQ2: =TR(tickers!$B$1402:$B$1426,"TR.TotalReturn.date;TR.TotalReturn",config!$B$10) | HU2: =TR(tickers!$B$1427:$B$1451,"TR.TotalReturn.date;TR.TotalReturn",config!$B$10) | HY2: =TR(tickers!$B$1452:$B$1476,"TR.TotalReturn.date;TR.TotalReturn",config!$B$10) | IC2: =TR(tickers!$B$1477:$B$1501,"TR.TotalReturn.date;TR.TotalReturn",config!$B$10)

Sheet px_last_2025
A1: tickers B2:B26 | E1: tickers B27:B51 | I1: tickers B52:B76 | M1: tickers B77:B101 | Q1: tickers B102:B126 | U1: tickers B127:B151 | Y1: tickers B152:B176 | AC1: tickers B177:B201 | AG1: tickers B202:B226 | AK1: tickers B227:B251 | AO1: tickers B252:B276 | AS1: tickers B277:B301 | AW1: tickers B302:B326 | BA1: tickers B327:B351 | BE1: tickers B352:B376 | BI1: tickers B377:B401 | BM1: tickers B402:B426 | BQ1: tickers B427:B451 | BU1: tickers B452:B476 | BY1: tickers B477:B501 | CC1: tickers B502:B526 | CG1: tickers B527:B551 | CK1: tickers B552:B576 | CO1: tickers B577:B601 | CS1: tickers B602:B626 | CW1: tickers B627:B651 | DA1: tickers B652:B676 | DE1: tickers B677:B701 | DI1: tickers B702:B726 | DM1: tickers B727:B751 | DQ1: tickers B752:B776 | DU1: tickers B777:B801 | DY1: tickers B802:B826 | EC1: tickers B827:B851 | EG1: tickers B852:B876 | EK1: tickers B877:B901 | EO1: tickers B902:B926 | ES1: tickers B927:B951 | EW1: tickers B952:B976 | FA1: tickers B977:B1001 | FE1: tickers B1002:B1026 | FI1: tickers B1027:B1051 | FM1: tickers B1052:B1076 | FQ1: tickers B1077:B1101 | FU1: tickers B1102:B1126 | FY1: tickers B1127:B1151 | GC1: tickers B1152:B1176 | GG1: tickers B1177:B1201 | GK1: tickers B1202:B1226 | GO1: tickers B1227:B1251 | GS1: tickers B1252:B1276 | GW1: tickers B1277:B1301 | HA1: tickers B1302:B1326 | HE1: tickers B1327:B1351 | HI1: tickers B1352:B1376 | HM1: tickers B1377:B1401 | HQ1: tickers B1402:B1426 | HU1: tickers B1427:B1451 | HY1: tickers B1452:B1476 | IC1: tickers B1477:B1501
A2: =TR(tickers!$B$2:$B$26,"TR.PriceClose.date;TR.PriceClose",config!$B$10) | E2: =TR(tickers!$B$27:$B$51,"TR.PriceClose.date;TR.PriceClose",config!$B$10) | I2: =TR(tickers!$B$52:$B$76,"TR.PriceClose.date;TR.PriceClose",config!$B$10) | M2: =TR(tickers!$B$77:$B$101,"TR.PriceClose.date;TR.PriceClose",config!$B$10) | Q2: =TR(tickers!$B$102:$B$126,"TR.PriceClose.date;TR.PriceClose",config!$B$10) | U2: =TR(tickers!$B$127:$B$151,"TR.PriceClose.date;TR.PriceClose",config!$B$10) | Y2: =TR(tickers!$B$152:$B$176,"TR.PriceClose.date;TR.PriceClose",config!$B$10) | AC2: =TR(tickers!$B$177:$B$201,"TR.PriceClose.date;TR.PriceClose",config!$B$10) | AG2: =TR(tickers!$B$202:$B$226,"TR.PriceClose.date;TR.PriceClose",config!$B$10) | AK2: =TR(tickers!$B$227:$B$251,"TR.PriceClose.date;TR.PriceClose",config!$B$10) | AO2: =TR(tickers!$B$252:$B$276,"TR.PriceClose.date;TR.PriceClose",config!$B$10) | AS2: =TR(tickers!$B$277:$B$301,"TR.PriceClose.date;TR.PriceClose",config!$B$10) | AW2: =TR(tickers!$B$302:$B$326,"TR.PriceClose.date;TR.PriceClose",config!$B$10) | BA2: =TR(tickers!$B$327:$B$351,"TR.PriceClose.date;TR.PriceClose",config!$B$10) | BE2: =TR(tickers!$B$352:$B$376,"TR.PriceClose.date;TR.PriceClose",config!$B$10) | BI2: =TR(tickers!$B$377:$B$401,"TR.PriceClose.date;TR.PriceClose",config!$B$10) | BM2: =TR(tickers!$B$402:$B$426,"TR.PriceClose.date;TR.PriceClose",config!$B$10) | BQ2: =TR(tickers!$B$427:$B$451,"TR.PriceClose.date;TR.PriceClose",config!$B$10) | BU2: =TR(tickers!$B$452:$B$476,"TR.PriceClose.date;TR.PriceClose",config!$B$10) | BY2: =TR(tickers!$B$477:$B$501,"TR.PriceClose.date;TR.PriceClose",config!$B$10) | CC2: =TR(tickers!$B$502:$B$526,"TR.PriceClose.date;TR.PriceClose",config!$B$10) | CG2: =TR(tickers!$B$527:$B$551,"TR.PriceClose.date;TR.PriceClose",config!$B$10) | CK2: =TR(tickers!$B$552:$B$576,"TR.PriceClose.date;TR.PriceClose",config!$B$10) | CO2: =TR(tickers!$B$577:$B$601,"TR.PriceClose.date;TR.PriceClose",config!$B$10) | CS2: =TR(tickers!$B$602:$B$626,"TR.PriceClose.date;TR.PriceClose",config!$B$10) | CW2: =TR(tickers!$B$627:$B$651,"TR.PriceClose.date;TR.PriceClose",config!$B$10) | DA2: =TR(tickers!$B$652:$B$676,"TR.PriceClose.date;TR.PriceClose",config!$B$10) | DE2: =TR(tickers!$B$677:$B$701,"TR.PriceClose.date;TR.PriceClose",config!$B$10) | DI2: =TR(tickers!$B$702:$B$726,"TR.PriceClose.date;TR.PriceClose",config!$B$10) | DM2: =TR(tickers!$B$727:$B$751,"TR.PriceClose.date;TR.PriceClose",config!$B$10) | DQ2: =TR(tickers!$B$752:$B$776,"TR.PriceClose.date;TR.PriceClose",config!$B$10) | DU2: =TR(tickers!$B$777:$B$801,"TR.PriceClose.date;TR.PriceClose",config!$B$10) | DY2: =TR(tickers!$B$802:$B$826,"TR.PriceClose.date;TR.PriceClose",config!$B$10) | EC2: =TR(tickers!$B$827:$B$851,"TR.PriceClose.date;TR.PriceClose",config!$B$10) | EG2: =TR(tickers!$B$852:$B$876,"TR.PriceClose.date;TR.PriceClose",config!$B$10) | EK2: =TR(tickers!$B$877:$B$901,"TR.PriceClose.date;TR.PriceClose",config!$B$10) | EO2: =TR(tickers!$B$902:$B$926,"TR.PriceClose.date;TR.PriceClose",config!$B$10) | ES2: =TR(tickers!$B$927:$B$951,"TR.PriceClose.date;TR.PriceClose",config!$B$10) | EW2: =TR(tickers!$B$952:$B$976,"TR.PriceClose.date;TR.PriceClose",config!$B$10) | FA2: =TR(tickers!$B$977:$B$1001,"TR.PriceClose.date;TR.PriceClose",config!$B$10) | FE2: =TR(tickers!$B$1002:$B$1026,"TR.PriceClose.date;TR.PriceClose",config!$B$10) | FI2: =TR(tickers!$B$1027:$B$1051,"TR.PriceClose.date;TR.PriceClose",config!$B$10) | FM2: =TR(tickers!$B$1052:$B$1076,"TR.PriceClose.date;TR.PriceClose",config!$B$10) | FQ2: =TR(tickers!$B$1077:$B$1101,"TR.PriceClose.date;TR.PriceClose",config!$B$10) | FU2: =TR(tickers!$B$1102:$B$1126,"TR.PriceClose.date;TR.PriceClose",config!$B$10) | FY2: =TR(tickers!$B$1127:$B$1151,"TR.PriceClose.date;TR.PriceClose",config!$B$10) | GC2: =TR(tickers!$B$1152:$B$1176,"TR.PriceClose.date;TR.PriceClose",config!$B$10) | GG2: =TR(tickers!$B$1177:$B$1201,"TR.PriceClose.date;TR.PriceClose",config!$B$10) | GK2: =TR(tickers!$B$1202:$B$1226,"TR.PriceClose.date;TR.PriceClose",config!$B$10) | GO2: =TR(tickers!$B$1227:$B$1251,"TR.PriceClose.date;TR.PriceClose",config!$B$10) | GS2: =TR(tickers!$B$1252:$B$1276,"TR.PriceClose.date;TR.PriceClose",config!$B$10) | GW2: =TR(tickers!$B$1277:$B$1301,"TR.PriceClose.date;TR.PriceClose",config!$B$10) | HA2: =TR(tickers!$B$1302:$B$1326,"TR.PriceClose.date;TR.PriceClose",config!$B$10) | HE2: =TR(tickers!$B$1327:$B$1351,"TR.PriceClose.date;TR.PriceClose",config!$B$10) | HI2: =TR(tickers!$B$1352:$B$1376,"TR.PriceClose.date;TR.PriceClose",config!$B$10) | HM2: =TR(tickers!$B$1377:$B$1401,"TR.PriceClose.date;TR.PriceClose",config!$B$10) | HQ2: =TR(tickers!$B$1402:$B$1426,"TR.PriceClose.date;TR.PriceClose",config!$B$10) | HU2: =TR(tickers!$B$1427:$B$1451,"TR.PriceClose.date;TR.PriceClose",config!$B$10) | HY2: =TR(tickers!$B$1452:$B$1476,"TR.PriceClose.date;TR.PriceClose",config!$B$10) | IC2: =TR(tickers!$B$1477:$B$1501,"TR.PriceClose.date;TR.PriceClose",config!$B$10)

Sheet px_volume_2025
A1: tickers B2:B26 | E1: tickers B27:B51 | I1: tickers B52:B76 | M1: tickers B77:B101 | Q1: tickers B102:B126 | U1: tickers B127:B151 | Y1: tickers B152:B176 | AC1: tickers B177:B201 | AG1: tickers B202:B226 | AK1: tickers B227:B251 | AO1: tickers B252:B276 | AS1: tickers B277:B301 | AW1: tickers B302:B326 | BA1: tickers B327:B351 | BE1: tickers B352:B376 | BI1: tickers B377:B401 | BM1: tickers B402:B426 | BQ1: tickers B427:B451 | BU1: tickers B452:B476 | BY1: tickers B477:B501 | CC1: tickers B502:B526 | CG1: tickers B527:B551 | CK1: tickers B552:B576 | CO1: tickers B577:B601 | CS1: tickers B602:B626 | CW1: tickers B627:B651 | DA1: tickers B652:B676 | DE1: tickers B677:B701 | DI1: tickers B702:B726 | DM1: tickers B727:B751 | DQ1: tickers B752:B776 | DU1: tickers B777:B801 | DY1: tickers B802:B826 | EC1: tickers B827:B851 | EG1: tickers B852:B876 | EK1: tickers B877:B901 | EO1: tickers B902:B926 | ES1: tickers B927:B951 | EW1: tickers B952:B976 | FA1: tickers B977:B1001 | FE1: tickers B1002:B1026 | FI1: tickers B1027:B1051 | FM1: tickers B1052:B1076 | FQ1: tickers B1077:B1101 | FU1: tickers B1102:B1126 | FY1: tickers B1127:B1151 | GC1: tickers B1152:B1176 | GG1: tickers B1177:B1201 | GK1: tickers B1202:B1226 | GO1: tickers B1227:B1251 | GS1: tickers B1252:B1276 | GW1: tickers B1277:B1301 | HA1: tickers B1302:B1326 | HE1: tickers B1327:B1351 | HI1: tickers B1352:B1376 | HM1: tickers B1377:B1401 | HQ1: tickers B1402:B1426 | HU1: tickers B1427:B1451 | HY1: tickers B1452:B1476 | IC1: tickers B1477:B1501
A2: =TR(tickers!$B$2:$B$26,"TR.Volume.date;TR.Volume",config!$B$10) | E2: =TR(tickers!$B$27:$B$51,"TR.Volume.date;TR.Volume",config!$B$10) | I2: =TR(tickers!$B$52:$B$76,"TR.Volume.date;TR.Volume",config!$B$10) | M2: =TR(tickers!$B$77:$B$101,"TR.Volume.date;TR.Volume",config!$B$10) | Q2: =TR(tickers!$B$102:$B$126,"TR.Volume.date;TR.Volume",config!$B$10) | U2: =TR(tickers!$B$127:$B$151,"TR.Volume.date;TR.Volume",config!$B$10) | Y2: =TR(tickers!$B$152:$B$176,"TR.Volume.date;TR.Volume",config!$B$10) | AC2: =TR(tickers!$B$177:$B$201,"TR.Volume.date;TR.Volume",config!$B$10) | AG2: =TR(tickers!$B$202:$B$226,"TR.Volume.date;TR.Volume",config!$B$10) | AK2: =TR(tickers!$B$227:$B$251,"TR.Volume.date;TR.Volume",config!$B$10) | AO2: =TR(tickers!$B$252:$B$276,"TR.Volume.date;TR.Volume",config!$B$10) | AS2: =TR(tickers!$B$277:$B$301,"TR.Volume.date;TR.Volume",config!$B$10) | AW2: =TR(tickers!$B$302:$B$326,"TR.Volume.date;TR.Volume",config!$B$10) | BA2: =TR(tickers!$B$327:$B$351,"TR.Volume.date;TR.Volume",config!$B$10) | BE2: =TR(tickers!$B$352:$B$376,"TR.Volume.date;TR.Volume",config!$B$10) | BI2: =TR(tickers!$B$377:$B$401,"TR.Volume.date;TR.Volume",config!$B$10) | BM2: =TR(tickers!$B$402:$B$426,"TR.Volume.date;TR.Volume",config!$B$10) | BQ2: =TR(tickers!$B$427:$B$451,"TR.Volume.date;TR.Volume",config!$B$10) | BU2: =TR(tickers!$B$452:$B$476,"TR.Volume.date;TR.Volume",config!$B$10) | BY2: =TR(tickers!$B$477:$B$501,"TR.Volume.date;TR.Volume",config!$B$10) | CC2: =TR(tickers!$B$502:$B$526,"TR.Volume.date;TR.Volume",config!$B$10) | CG2: =TR(tickers!$B$527:$B$551,"TR.Volume.date;TR.Volume",config!$B$10) | CK2: =TR(tickers!$B$552:$B$576,"TR.Volume.date;TR.Volume",config!$B$10) | CO2: =TR(tickers!$B$577:$B$601,"TR.Volume.date;TR.Volume",config!$B$10) | CS2: =TR(tickers!$B$602:$B$626,"TR.Volume.date;TR.Volume",config!$B$10) | CW2: =TR(tickers!$B$627:$B$651,"TR.Volume.date;TR.Volume",config!$B$10) | DA2: =TR(tickers!$B$652:$B$676,"TR.Volume.date;TR.Volume",config!$B$10) | DE2: =TR(tickers!$B$677:$B$701,"TR.Volume.date;TR.Volume",config!$B$10) | DI2: =TR(tickers!$B$702:$B$726,"TR.Volume.date;TR.Volume",config!$B$10) | DM2: =TR(tickers!$B$727:$B$751,"TR.Volume.date;TR.Volume",config!$B$10) | DQ2: =TR(tickers!$B$752:$B$776,"TR.Volume.date;TR.Volume",config!$B$10) | DU2: =TR(tickers!$B$777:$B$801,"TR.Volume.date;TR.Volume",config!$B$10) | DY2: =TR(tickers!$B$802:$B$826,"TR.Volume.date;TR.Volume",config!$B$10) | EC2: =TR(tickers!$B$827:$B$851,"TR.Volume.date;TR.Volume",config!$B$10) | EG2: =TR(tickers!$B$852:$B$876,"TR.Volume.date;TR.Volume",config!$B$10) | EK2: =TR(tickers!$B$877:$B$901,"TR.Volume.date;TR.Volume",config!$B$10) | EO2: =TR(tickers!$B$902:$B$926,"TR.Volume.date;TR.Volume",config!$B$10) | ES2: =TR(tickers!$B$927:$B$951,"TR.Volume.date;TR.Volume",config!$B$10) | EW2: =TR(tickers!$B$952:$B$976,"TR.Volume.date;TR.Volume",config!$B$10) | FA2: =TR(tickers!$B$977:$B$1001,"TR.Volume.date;TR.Volume",config!$B$10) | FE2: =TR(tickers!$B$1002:$B$1026,"TR.Volume.date;TR.Volume",config!$B$10) | FI2: =TR(tickers!$B$1027:$B$1051,"TR.Volume.date;TR.Volume",config!$B$10) | FM2: =TR(tickers!$B$1052:$B$1076,"TR.Volume.date;TR.Volume",config!$B$10) | FQ2: =TR(tickers!$B$1077:$B$1101,"TR.Volume.date;TR.Volume",config!$B$10) | FU2: =TR(tickers!$B$1102:$B$1126,"TR.Volume.date;TR.Volume",config!$B$10) | FY2: =TR(tickers!$B$1127:$B$1151,"TR.Volume.date;TR.Volume",config!$B$10) | GC2: =TR(tickers!$B$1152:$B$1176,"TR.Volume.date;TR.Volume",config!$B$10) | GG2: =TR(tickers!$B$1177:$B$1201,"TR.Volume.date;TR.Volume",config!$B$10) | GK2: =TR(tickers!$B$1202:$B$1226,"TR.Volume.date;TR.Volume",config!$B$10) | GO2: =TR(tickers!$B$1227:$B$1251,"TR.Volume.date;TR.Volume",config!$B$10) | GS2: =TR(tickers!$B$1252:$B$1276,"TR.Volume.date;TR.Volume",config!$B$10) | GW2: =TR(tickers!$B$1277:$B$1301,"TR.Volume.date;TR.Volume",config!$B$10) | HA2: =TR(tickers!$B$1302:$B$1326,"TR.Volume.date;TR.Volume",config!$B$10) | HE2: =TR(tickers!$B$1327:$B$1351,"TR.Volume.date;TR.Volume",config!$B$10) | HI2: =TR(tickers!$B$1352:$B$1376,"TR.Volume.date;TR.Volume",config!$B$10) | HM2: =TR(tickers!$B$1377:$B$1401,"TR.Volume.date;TR.Volume",config!$B$10) | HQ2: =TR(tickers!$B$1402:$B$1426,"TR.Volume.date;TR.Volume",config!$B$10) | HU2: =TR(tickers!$B$1427:$B$1451,"TR.Volume.date;TR.Volume",config!$B$10) | HY2: =TR(tickers!$B$1452:$B$1476,"TR.Volume.date;TR.Volume",config!$B$10) | IC2: =TR(tickers!$B$1477:$B$1501,"TR.Volume.date;TR.Volume",config!$B$10)

Sheet static
A1: tickers B2:B201 | H1: tickers B202:B401 | O1: tickers B402:B601 | V1: tickers B602:B801 | AC1: tickers B802:B1001 | AJ1: tickers B1002:B1201 | AQ1: tickers B1202:B1401 | AX1: tickers B1402:B1601
A2: =TR(tickers!$B$2:$B$201,"TR.CommonName;TR.GICSSector;TR.GICSIndustry;TR.FreeFloatPct;TR.SharesOutstanding","CH=Fd RH=IN") | H2: =TR(tickers!$B$202:$B$401,"TR.CommonName;TR.GICSSector;TR.GICSIndustry;TR.FreeFloatPct;TR.SharesOutstanding","CH=Fd RH=IN") | O2: =TR(tickers!$B$402:$B$601,"TR.CommonName;TR.GICSSector;TR.GICSIndustry;TR.FreeFloatPct;TR.SharesOutstanding","CH=Fd RH=IN") | V2: =TR(tickers!$B$602:$B$801,"TR.CommonName;TR.GICSSector;TR.GICSIndustry;TR.FreeFloatPct;TR.SharesOutstanding","CH=Fd RH=IN") | AC2: =TR(tickers!$B$802:$B$1001,"TR.CommonName;TR.GICSSector;TR.GICSIndustry;TR.FreeFloatPct;TR.SharesOutstanding","CH=Fd RH=IN") | AJ2: =TR(tickers!$B$1002:$B$1201,"TR.CommonName;TR.GICSSector;TR.GICSIndustry;TR.FreeFloatPct;TR.SharesOutstanding","CH=Fd RH=IN") | AQ2: =TR(tickers!$B$1202:$B$1401,"TR.CommonName;TR.GICSSector;TR.GICSIndustry;TR.FreeFloatPct;TR.SharesOutstanding","CH=Fd RH=IN") | AX2: =TR(tickers!$B$1402:$B$1601,"TR.CommonName;TR.GICSSector;TR.GICSIndustry;TR.FreeFloatPct;TR.SharesOutstanding","CH=Fd RH=IN")

Sheet msci
A1: snapshot 2015-02-27
A2: =TR(config!$B$3,"TR.IndexConstituentRIC;TR.IndexConstituentWeightPercent;TR.IndexConstituentName","SDate=2015-02-27 CH=Fd RH=IN")
A81: snapshot 2015-05-29
A82: =TR(config!$B$3,"TR.IndexConstituentRIC;TR.IndexConstituentWeightPercent;TR.IndexConstituentName","SDate=2015-05-29 CH=Fd RH=IN")
A161: snapshot 2015-08-31
A162: =TR(config!$B$3,"TR.IndexConstituentRIC;TR.IndexConstituentWeightPercent;TR.IndexConstituentName","SDate=2015-08-31 CH=Fd RH=IN")
A241: snapshot 2015-11-30
A242: =TR(config!$B$3,"TR.IndexConstituentRIC;TR.IndexConstituentWeightPercent;TR.IndexConstituentName","SDate=2015-11-30 CH=Fd RH=IN")
A321: snapshot 2016-02-29
A322: =TR(config!$B$3,"TR.IndexConstituentRIC;TR.IndexConstituentWeightPercent;TR.IndexConstituentName","SDate=2016-02-29 CH=Fd RH=IN")
A401: snapshot 2016-05-31
A402: =TR(config!$B$3,"TR.IndexConstituentRIC;TR.IndexConstituentWeightPercent;TR.IndexConstituentName","SDate=2016-05-31 CH=Fd RH=IN")
A481: snapshot 2016-08-31
A482: =TR(config!$B$3,"TR.IndexConstituentRIC;TR.IndexConstituentWeightPercent;TR.IndexConstituentName","SDate=2016-08-31 CH=Fd RH=IN")
A561: snapshot 2016-11-30
A562: =TR(config!$B$3,"TR.IndexConstituentRIC;TR.IndexConstituentWeightPercent;TR.IndexConstituentName","SDate=2016-11-30 CH=Fd RH=IN")
A641: snapshot 2017-02-28
A642: =TR(config!$B$3,"TR.IndexConstituentRIC;TR.IndexConstituentWeightPercent;TR.IndexConstituentName","SDate=2017-02-28 CH=Fd RH=IN")
A721: snapshot 2017-05-31
A722: =TR(config!$B$3,"TR.IndexConstituentRIC;TR.IndexConstituentWeightPercent;TR.IndexConstituentName","SDate=2017-05-31 CH=Fd RH=IN")
A801: snapshot 2017-08-31
A802: =TR(config!$B$3,"TR.IndexConstituentRIC;TR.IndexConstituentWeightPercent;TR.IndexConstituentName","SDate=2017-08-31 CH=Fd RH=IN")
A881: snapshot 2017-11-30
A882: =TR(config!$B$3,"TR.IndexConstituentRIC;TR.IndexConstituentWeightPercent;TR.IndexConstituentName","SDate=2017-11-30 CH=Fd RH=IN")
A961: snapshot 2018-02-28
A962: =TR(config!$B$3,"TR.IndexConstituentRIC;TR.IndexConstituentWeightPercent;TR.IndexConstituentName","SDate=2018-02-28 CH=Fd RH=IN")
A1041: snapshot 2018-05-31
A1042: =TR(config!$B$3,"TR.IndexConstituentRIC;TR.IndexConstituentWeightPercent;TR.IndexConstituentName","SDate=2018-05-31 CH=Fd RH=IN")
A1121: snapshot 2018-08-31
A1122: =TR(config!$B$3,"TR.IndexConstituentRIC;TR.IndexConstituentWeightPercent;TR.IndexConstituentName","SDate=2018-08-31 CH=Fd RH=IN")
A1201: snapshot 2018-11-30
A1202: =TR(config!$B$3,"TR.IndexConstituentRIC;TR.IndexConstituentWeightPercent;TR.IndexConstituentName","SDate=2018-11-30 CH=Fd RH=IN")
A1281: snapshot 2019-02-28
A1282: =TR(config!$B$3,"TR.IndexConstituentRIC;TR.IndexConstituentWeightPercent;TR.IndexConstituentName","SDate=2019-02-28 CH=Fd RH=IN")
A1361: snapshot 2019-05-31
A1362: =TR(config!$B$3,"TR.IndexConstituentRIC;TR.IndexConstituentWeightPercent;TR.IndexConstituentName","SDate=2019-05-31 CH=Fd RH=IN")
A1441: snapshot 2019-08-30
A1442: =TR(config!$B$3,"TR.IndexConstituentRIC;TR.IndexConstituentWeightPercent;TR.IndexConstituentName","SDate=2019-08-30 CH=Fd RH=IN")
A1521: snapshot 2019-11-29
A1522: =TR(config!$B$3,"TR.IndexConstituentRIC;TR.IndexConstituentWeightPercent;TR.IndexConstituentName","SDate=2019-11-29 CH=Fd RH=IN")
...

Sheet ftse
A1: snapshot 2015-02-27
A2: =TR(config!$B$4,"TR.IndexConstituentRIC;TR.IndexConstituentWeightPercent;TR.IndexConstituentName","SDate=2015-02-27 CH=Fd RH=IN")
A81: snapshot 2015-05-29
A82: =TR(config!$B$4,"TR.IndexConstituentRIC;TR.IndexConstituentWeightPercent;TR.IndexConstituentName","SDate=2015-05-29 CH=Fd RH=IN")
A161: snapshot 2015-08-31
A162: =TR(config!$B$4,"TR.IndexConstituentRIC;TR.IndexConstituentWeightPercent;TR.IndexConstituentName","SDate=2015-08-31 CH=Fd RH=IN")
A241: snapshot 2015-11-30
A242: =TR(config!$B$4,"TR.IndexConstituentRIC;TR.IndexConstituentWeightPercent;TR.IndexConstituentName","SDate=2015-11-30 CH=Fd RH=IN")
A321: snapshot 2016-02-29
A322: =TR(config!$B$4,"TR.IndexConstituentRIC;TR.IndexConstituentWeightPercent;TR.IndexConstituentName","SDate=2016-02-29 CH=Fd RH=IN")
A401: snapshot 2016-05-31
A402: =TR(config!$B$4,"TR.IndexConstituentRIC;TR.IndexConstituentWeightPercent;TR.IndexConstituentName","SDate=2016-05-31 CH=Fd RH=IN")
A481: snapshot 2016-08-31
A482: =TR(config!$B$4,"TR.IndexConstituentRIC;TR.IndexConstituentWeightPercent;TR.IndexConstituentName","SDate=2016-08-31 CH=Fd RH=IN")
A561: snapshot 2016-11-30
A562: =TR(config!$B$4,"TR.IndexConstituentRIC;TR.IndexConstituentWeightPercent;TR.IndexConstituentName","SDate=2016-11-30 CH=Fd RH=IN")
A641: snapshot 2017-02-28
A642: =TR(config!$B$4,"TR.IndexConstituentRIC;TR.IndexConstituentWeightPercent;TR.IndexConstituentName","SDate=2017-02-28 CH=Fd RH=IN")
A721: snapshot 2017-05-31
A722: =TR(config!$B$4,"TR.IndexConstituentRIC;TR.IndexConstituentWeightPercent;TR.IndexConstituentName","SDate=2017-05-31 CH=Fd RH=IN")
A801: snapshot 2017-08-31
A802: =TR(config!$B$4,"TR.IndexConstituentRIC;TR.IndexConstituentWeightPercent;TR.IndexConstituentName","SDate=2017-08-31 CH=Fd RH=IN")
A881: snapshot 2017-11-30
A882: =TR(config!$B$4,"TR.IndexConstituentRIC;TR.IndexConstituentWeightPercent;TR.IndexConstituentName","SDate=2017-11-30 CH=Fd RH=IN")
A961: snapshot 2018-02-28
A962: =TR(config!$B$4,"TR.IndexConstituentRIC;TR.IndexConstituentWeightPercent;TR.IndexConstituentName","SDate=2018-02-28 CH=Fd RH=IN")
A1041: snapshot 2018-05-31
A1042: =TR(config!$B$4,"TR.IndexConstituentRIC;TR.IndexConstituentWeightPercent;TR.IndexConstituentName","SDate=2018-05-31 CH=Fd RH=IN")
A1121: snapshot 2018-08-31
A1122: =TR(config!$B$4,"TR.IndexConstituentRIC;TR.IndexConstituentWeightPercent;TR.IndexConstituentName","SDate=2018-08-31 CH=Fd RH=IN")
A1201: snapshot 2018-11-30
A1202: =TR(config!$B$4,"TR.IndexConstituentRIC;TR.IndexConstituentWeightPercent;TR.IndexConstituentName","SDate=2018-11-30 CH=Fd RH=IN")
A1281: snapshot 2019-02-28
A1282: =TR(config!$B$4,"TR.IndexConstituentRIC;TR.IndexConstituentWeightPercent;TR.IndexConstituentName","SDate=2019-02-28 CH=Fd RH=IN")
A1361: snapshot 2019-05-31
A1362: =TR(config!$B$4,"TR.IndexConstituentRIC;TR.IndexConstituentWeightPercent;TR.IndexConstituentName","SDate=2019-05-31 CH=Fd RH=IN")
A1441: snapshot 2019-08-30
A1442: =TR(config!$B$4,"TR.IndexConstituentRIC;TR.IndexConstituentWeightPercent;TR.IndexConstituentName","SDate=2019-08-30 CH=Fd RH=IN")
A1521: snapshot 2019-11-29
A1522: =TR(config!$B$4,"TR.IndexConstituentRIC;TR.IndexConstituentWeightPercent;TR.IndexConstituentName","SDate=2019-11-29 CH=Fd RH=IN")
...

Sheet universe
A1: snapshot 2015-02-27
A2: =TR(config!$B$20,"TR.IndexConstituentRIC","SDate=2015-02-27 CH=Fd RH=IN")
A1101: snapshot 2015-05-29
A1102: =TR(config!$B$20,"TR.IndexConstituentRIC","SDate=2015-05-29 CH=Fd RH=IN")
A2201: snapshot 2015-08-31
A2202: =TR(config!$B$20,"TR.IndexConstituentRIC","SDate=2015-08-31 CH=Fd RH=IN")
A3301: snapshot 2015-11-30
A3302: =TR(config!$B$20,"TR.IndexConstituentRIC","SDate=2015-11-30 CH=Fd RH=IN")
A4401: snapshot 2016-02-29
A4402: =TR(config!$B$20,"TR.IndexConstituentRIC","SDate=2016-02-29 CH=Fd RH=IN")
A5501: snapshot 2016-05-31
A5502: =TR(config!$B$20,"TR.IndexConstituentRIC","SDate=2016-05-31 CH=Fd RH=IN")
A6601: snapshot 2016-08-31
A6602: =TR(config!$B$20,"TR.IndexConstituentRIC","SDate=2016-08-31 CH=Fd RH=IN")
A7701: snapshot 2016-11-30
A7702: =TR(config!$B$20,"TR.IndexConstituentRIC","SDate=2016-11-30 CH=Fd RH=IN")
A8801: snapshot 2017-02-28
A8802: =TR(config!$B$20,"TR.IndexConstituentRIC","SDate=2017-02-28 CH=Fd RH=IN")
A9901: snapshot 2017-05-31
A9902: =TR(config!$B$20,"TR.IndexConstituentRIC","SDate=2017-05-31 CH=Fd RH=IN")
A11001: snapshot 2017-08-31
A11002: =TR(config!$B$20,"TR.IndexConstituentRIC","SDate=2017-08-31 CH=Fd RH=IN")
A12101: snapshot 2017-11-30
A12102: =TR(config!$B$20,"TR.IndexConstituentRIC","SDate=2017-11-30 CH=Fd RH=IN")
A13201: snapshot 2018-02-28
A13202: =TR(config!$B$20,"TR.IndexConstituentRIC","SDate=2018-02-28 CH=Fd RH=IN")
A14301: snapshot 2018-05-31
A14302: =TR(config!$B$20,"TR.IndexConstituentRIC","SDate=2018-05-31 CH=Fd RH=IN")
A15401: snapshot 2018-08-31
A15402: =TR(config!$B$20,"TR.IndexConstituentRIC","SDate=2018-08-31 CH=Fd RH=IN")
A16501: snapshot 2018-11-30
A16502: =TR(config!$B$20,"TR.IndexConstituentRIC","SDate=2018-11-30 CH=Fd RH=IN")
A17601: snapshot 2019-02-28
A17602: =TR(config!$B$20,"TR.IndexConstituentRIC","SDate=2019-02-28 CH=Fd RH=IN")
A18701: snapshot 2019-05-31
A18702: =TR(config!$B$20,"TR.IndexConstituentRIC","SDate=2019-05-31 CH=Fd RH=IN")
A19801: snapshot 2019-08-30
A19802: =TR(config!$B$20,"TR.IndexConstituentRIC","SDate=2019-08-30 CH=Fd RH=IN")
A20901: snapshot 2019-11-29
A20902: =TR(config!$B$20,"TR.IndexConstituentRIC","SDate=2019-11-29 CH=Fd RH=IN")
...

Sheet ff_hist
A1: tickers B2:B51 | E1: tickers B52:B101 | I1: tickers B102:B151 | M1: tickers B152:B201 | Q1: tickers B202:B251 | U1: tickers B252:B301 | Y1: tickers B302:B351 | AC1: tickers B352:B401 | AG1: tickers B402:B451 | AK1: tickers B452:B501 | AO1: tickers B502:B551 | AS1: tickers B552:B601 | AW1: tickers B602:B651 | BA1: tickers B652:B701 | BE1: tickers B702:B751 | BI1: tickers B752:B801 | BM1: tickers B802:B851 | BQ1: tickers B852:B901 | BU1: tickers B902:B951 | BY1: tickers B952:B1001 | CC1: tickers B1002:B1051 | CG1: tickers B1052:B1101 | CK1: tickers B1102:B1151 | CO1: tickers B1152:B1201 | CS1: tickers B1202:B1251 | CW1: tickers B1252:B1301 | DA1: tickers B1302:B1351 | DE1: tickers B1352:B1401 | DI1: tickers B1402:B1451 | DM1: tickers B1452:B1501
A2: =TR(tickers!$B$2:$B$51,"TR.FreeFloatPct.date;TR.FreeFloatPct",config!$B$8) | E2: =TR(tickers!$B$52:$B$101,"TR.FreeFloatPct.date;TR.FreeFloatPct",config!$B$8) | I2: =TR(tickers!$B$102:$B$151,"TR.FreeFloatPct.date;TR.FreeFloatPct",config!$B$8) | M2: =TR(tickers!$B$152:$B$201,"TR.FreeFloatPct.date;TR.FreeFloatPct",config!$B$8) | Q2: =TR(tickers!$B$202:$B$251,"TR.FreeFloatPct.date;TR.FreeFloatPct",config!$B$8) | U2: =TR(tickers!$B$252:$B$301,"TR.FreeFloatPct.date;TR.FreeFloatPct",config!$B$8) | Y2: =TR(tickers!$B$302:$B$351,"TR.FreeFloatPct.date;TR.FreeFloatPct",config!$B$8) | AC2: =TR(tickers!$B$352:$B$401,"TR.FreeFloatPct.date;TR.FreeFloatPct",config!$B$8) | AG2: =TR(tickers!$B$402:$B$451,"TR.FreeFloatPct.date;TR.FreeFloatPct",config!$B$8) | AK2: =TR(tickers!$B$452:$B$501,"TR.FreeFloatPct.date;TR.FreeFloatPct",config!$B$8) | AO2: =TR(tickers!$B$502:$B$551,"TR.FreeFloatPct.date;TR.FreeFloatPct",config!$B$8) | AS2: =TR(tickers!$B$552:$B$601,"TR.FreeFloatPct.date;TR.FreeFloatPct",config!$B$8) | AW2: =TR(tickers!$B$602:$B$651,"TR.FreeFloatPct.date;TR.FreeFloatPct",config!$B$8) | BA2: =TR(tickers!$B$652:$B$701,"TR.FreeFloatPct.date;TR.FreeFloatPct",config!$B$8) | BE2: =TR(tickers!$B$702:$B$751,"TR.FreeFloatPct.date;TR.FreeFloatPct",config!$B$8) | BI2: =TR(tickers!$B$752:$B$801,"TR.FreeFloatPct.date;TR.FreeFloatPct",config!$B$8) | BM2: =TR(tickers!$B$802:$B$851,"TR.FreeFloatPct.date;TR.FreeFloatPct",config!$B$8) | BQ2: =TR(tickers!$B$852:$B$901,"TR.FreeFloatPct.date;TR.FreeFloatPct",config!$B$8) | BU2: =TR(tickers!$B$902:$B$951,"TR.FreeFloatPct.date;TR.FreeFloatPct",config!$B$8) | BY2: =TR(tickers!$B$952:$B$1001,"TR.FreeFloatPct.date;TR.FreeFloatPct",config!$B$8) | CC2: =TR(tickers!$B$1002:$B$1051,"TR.FreeFloatPct.date;TR.FreeFloatPct",config!$B$8) | CG2: =TR(tickers!$B$1052:$B$1101,"TR.FreeFloatPct.date;TR.FreeFloatPct",config!$B$8) | CK2: =TR(tickers!$B$1102:$B$1151,"TR.FreeFloatPct.date;TR.FreeFloatPct",config!$B$8) | CO2: =TR(tickers!$B$1152:$B$1201,"TR.FreeFloatPct.date;TR.FreeFloatPct",config!$B$8) | CS2: =TR(tickers!$B$1202:$B$1251,"TR.FreeFloatPct.date;TR.FreeFloatPct",config!$B$8) | CW2: =TR(tickers!$B$1252:$B$1301,"TR.FreeFloatPct.date;TR.FreeFloatPct",config!$B$8) | DA2: =TR(tickers!$B$1302:$B$1351,"TR.FreeFloatPct.date;TR.FreeFloatPct",config!$B$8) | DE2: =TR(tickers!$B$1352:$B$1401,"TR.FreeFloatPct.date;TR.FreeFloatPct",config!$B$8) | DI2: =TR(tickers!$B$1402:$B$1451,"TR.FreeFloatPct.date;TR.FreeFloatPct",config!$B$8) | DM2: =TR(tickers!$B$1452:$B$1501,"TR.FreeFloatPct.date;TR.FreeFloatPct",config!$B$8)

Sheet sh_hist
A1: tickers B2:B51 | E1: tickers B52:B101 | I1: tickers B102:B151 | M1: tickers B152:B201 | Q1: tickers B202:B251 | U1: tickers B252:B301 | Y1: tickers B302:B351 | AC1: tickers B352:B401 | AG1: tickers B402:B451 | AK1: tickers B452:B501 | AO1: tickers B502:B551 | AS1: tickers B552:B601 | AW1: tickers B602:B651 | BA1: tickers B652:B701 | BE1: tickers B702:B751 | BI1: tickers B752:B801 | BM1: tickers B802:B851 | BQ1: tickers B852:B901 | BU1: tickers B902:B951 | BY1: tickers B952:B1001 | CC1: tickers B1002:B1051 | CG1: tickers B1052:B1101 | CK1: tickers B1102:B1151 | CO1: tickers B1152:B1201 | CS1: tickers B1202:B1251 | CW1: tickers B1252:B1301 | DA1: tickers B1302:B1351 | DE1: tickers B1352:B1401 | DI1: tickers B1402:B1451 | DM1: tickers B1452:B1501
A2: =TR(tickers!$B$2:$B$51,"TR.SharesOutstanding.date;TR.SharesOutstanding",config!$B$8) | E2: =TR(tickers!$B$52:$B$101,"TR.SharesOutstanding.date;TR.SharesOutstanding",config!$B$8) | I2: =TR(tickers!$B$102:$B$151,"TR.SharesOutstanding.date;TR.SharesOutstanding",config!$B$8) | M2: =TR(tickers!$B$152:$B$201,"TR.SharesOutstanding.date;TR.SharesOutstanding",config!$B$8) | Q2: =TR(tickers!$B$202:$B$251,"TR.SharesOutstanding.date;TR.SharesOutstanding",config!$B$8) | U2: =TR(tickers!$B$252:$B$301,"TR.SharesOutstanding.date;TR.SharesOutstanding",config!$B$8) | Y2: =TR(tickers!$B$302:$B$351,"TR.SharesOutstanding.date;TR.SharesOutstanding",config!$B$8) | AC2: =TR(tickers!$B$352:$B$401,"TR.SharesOutstanding.date;TR.SharesOutstanding",config!$B$8) | AG2: =TR(tickers!$B$402:$B$451,"TR.SharesOutstanding.date;TR.SharesOutstanding",config!$B$8) | AK2: =TR(tickers!$B$452:$B$501,"TR.SharesOutstanding.date;TR.SharesOutstanding",config!$B$8) | AO2: =TR(tickers!$B$502:$B$551,"TR.SharesOutstanding.date;TR.SharesOutstanding",config!$B$8) | AS2: =TR(tickers!$B$552:$B$601,"TR.SharesOutstanding.date;TR.SharesOutstanding",config!$B$8) | AW2: =TR(tickers!$B$602:$B$651,"TR.SharesOutstanding.date;TR.SharesOutstanding",config!$B$8) | BA2: =TR(tickers!$B$652:$B$701,"TR.SharesOutstanding.date;TR.SharesOutstanding",config!$B$8) | BE2: =TR(tickers!$B$702:$B$751,"TR.SharesOutstanding.date;TR.SharesOutstanding",config!$B$8) | BI2: =TR(tickers!$B$752:$B$801,"TR.SharesOutstanding.date;TR.SharesOutstanding",config!$B$8) | BM2: =TR(tickers!$B$802:$B$851,"TR.SharesOutstanding.date;TR.SharesOutstanding",config!$B$8) | BQ2: =TR(tickers!$B$852:$B$901,"TR.SharesOutstanding.date;TR.SharesOutstanding",config!$B$8) | BU2: =TR(tickers!$B$902:$B$951,"TR.SharesOutstanding.date;TR.SharesOutstanding",config!$B$8) | BY2: =TR(tickers!$B$952:$B$1001,"TR.SharesOutstanding.date;TR.SharesOutstanding",config!$B$8) | CC2: =TR(tickers!$B$1002:$B$1051,"TR.SharesOutstanding.date;TR.SharesOutstanding",config!$B$8) | CG2: =TR(tickers!$B$1052:$B$1101,"TR.SharesOutstanding.date;TR.SharesOutstanding",config!$B$8) | CK2: =TR(tickers!$B$1102:$B$1151,"TR.SharesOutstanding.date;TR.SharesOutstanding",config!$B$8) | CO2: =TR(tickers!$B$1152:$B$1201,"TR.SharesOutstanding.date;TR.SharesOutstanding",config!$B$8) | CS2: =TR(tickers!$B$1202:$B$1251,"TR.SharesOutstanding.date;TR.SharesOutstanding",config!$B$8) | CW2: =TR(tickers!$B$1252:$B$1301,"TR.SharesOutstanding.date;TR.SharesOutstanding",config!$B$8) | DA2: =TR(tickers!$B$1302:$B$1351,"TR.SharesOutstanding.date;TR.SharesOutstanding",config!$B$8) | DE2: =TR(tickers!$B$1352:$B$1401,"TR.SharesOutstanding.date;TR.SharesOutstanding",config!$B$8) | DI2: =TR(tickers!$B$1402:$B$1451,"TR.SharesOutstanding.date;TR.SharesOutstanding",config!$B$8) | DM2: =TR(tickers!$B$1452:$B$1501,"TR.SharesOutstanding.date;TR.SharesOutstanding",config!$B$8)

Sheet kepemilikan_asing
A1: tickers B2:B201 | E1: tickers B202:B401 | I1: tickers B402:B601 | M1: tickers B602:B801 | Q1: tickers B802:B1001 | U1: tickers B1002:B1201 | Y1: tickers B1202:B1401 | AC1: tickers B1402:B1601
A2: =TR(tickers!$B$2:$B$201,config!$C$92&".date;"&config!$C$92,config!$D$92) | E2: =TR(tickers!$B$202:$B$401,config!$C$92&".date;"&config!$C$92,config!$D$92) | I2: =TR(tickers!$B$402:$B$601,config!$C$92&".date;"&config!$C$92,config!$D$92) | M2: =TR(tickers!$B$602:$B$801,config!$C$92&".date;"&config!$C$92,config!$D$92) | Q2: =TR(tickers!$B$802:$B$1001,config!$C$92&".date;"&config!$C$92,config!$D$92) | U2: =TR(tickers!$B$1002:$B$1201,config!$C$92&".date;"&config!$C$92,config!$D$92) | Y2: =TR(tickers!$B$1202:$B$1401,config!$C$92&".date;"&config!$C$92,config!$D$92) | AC2: =TR(tickers!$B$1402:$B$1601,config!$C$92&".date;"&config!$C$92,config!$D$92)

Sheet rating_bank
A1: tickers B2:B201 | E1: tickers B202:B401 | I1: tickers B402:B601 | M1: tickers B602:B801 | Q1: tickers B802:B1001 | U1: tickers B1002:B1201 | Y1: tickers B1202:B1401 | AC1: tickers B1402:B1601
A2: =TR(tickers!$B$2:$B$201,config!$C$93&".date;"&config!$C$93,config!$D$93) | E2: =TR(tickers!$B$202:$B$401,config!$C$93&".date;"&config!$C$93,config!$D$93) | I2: =TR(tickers!$B$402:$B$601,config!$C$93&".date;"&config!$C$93,config!$D$93) | M2: =TR(tickers!$B$602:$B$801,config!$C$93&".date;"&config!$C$93,config!$D$93) | Q2: =TR(tickers!$B$802:$B$1001,config!$C$93&".date;"&config!$C$93,config!$D$93) | U2: =TR(tickers!$B$1002:$B$1201,config!$C$93&".date;"&config!$C$93,config!$D$93) | Y2: =TR(tickers!$B$1202:$B$1401,config!$C$93&".date;"&config!$C$93,config!$D$93) | AC2: =TR(tickers!$B$1402:$B$1601,config!$C$93&".date;"&config!$C$93,config!$D$93)

Sheet total_aset
A1: tickers B2:B201 | E1: tickers B202:B401 | I1: tickers B402:B601 | M1: tickers B602:B801 | Q1: tickers B802:B1001 | U1: tickers B1002:B1201 | Y1: tickers B1202:B1401 | AC1: tickers B1402:B1601
A2: =TR(tickers!$B$2:$B$201,config!$C$94&".date;"&config!$C$94,config!$D$94) | E2: =TR(tickers!$B$202:$B$401,config!$C$94&".date;"&config!$C$94,config!$D$94) | I2: =TR(tickers!$B$402:$B$601,config!$C$94&".date;"&config!$C$94,config!$D$94) | M2: =TR(tickers!$B$602:$B$801,config!$C$94&".date;"&config!$C$94,config!$D$94) | Q2: =TR(tickers!$B$802:$B$1001,config!$C$94&".date;"&config!$C$94,config!$D$94) | U2: =TR(tickers!$B$1002:$B$1201,config!$C$94&".date;"&config!$C$94,config!$D$94) | Y2: =TR(tickers!$B$1202:$B$1401,config!$C$94&".date;"&config!$C$94,config!$D$94) | AC2: =TR(tickers!$B$1402:$B$1601,config!$C$94&".date;"&config!$C$94,config!$D$94)

Sheet total_deposito
A1: tickers B2:B201 | E1: tickers B202:B401 | I1: tickers B402:B601 | M1: tickers B602:B801 | Q1: tickers B802:B1001 | U1: tickers B1002:B1201 | Y1: tickers B1202:B1401 | AC1: tickers B1402:B1601
A2: =TR(tickers!$B$2:$B$201,config!$C$95&".date;"&config!$C$95,config!$D$95) | E2: =TR(tickers!$B$202:$B$401,config!$C$95&".date;"&config!$C$95,config!$D$95) | I2: =TR(tickers!$B$402:$B$601,config!$C$95&".date;"&config!$C$95,config!$D$95) | M2: =TR(tickers!$B$602:$B$801,config!$C$95&".date;"&config!$C$95,config!$D$95) | Q2: =TR(tickers!$B$802:$B$1001,config!$C$95&".date;"&config!$C$95,config!$D$95) | U2: =TR(tickers!$B$1002:$B$1201,config!$C$95&".date;"&config!$C$95,config!$D$95) | Y2: =TR(tickers!$B$1202:$B$1401,config!$C$95&".date;"&config!$C$95,config!$D$95) | AC2: =TR(tickers!$B$1402:$B$1601,config!$C$95&".date;"&config!$C$95,config!$D$95)

Sheet total_ekuitas
A1: tickers B2:B201 | E1: tickers B202:B401 | I1: tickers B402:B601 | M1: tickers B602:B801 | Q1: tickers B802:B1001 | U1: tickers B1002:B1201 | Y1: tickers B1202:B1401 | AC1: tickers B1402:B1601
A2: =TR(tickers!$B$2:$B$201,config!$C$96&".date;"&config!$C$96,config!$D$96) | E2: =TR(tickers!$B$202:$B$401,config!$C$96&".date;"&config!$C$96,config!$D$96) | I2: =TR(tickers!$B$402:$B$601,config!$C$96&".date;"&config!$C$96,config!$D$96) | M2: =TR(tickers!$B$602:$B$801,config!$C$96&".date;"&config!$C$96,config!$D$96) | Q2: =TR(tickers!$B$802:$B$1001,config!$C$96&".date;"&config!$C$96,config!$D$96) | U2: =TR(tickers!$B$1002:$B$1201,config!$C$96&".date;"&config!$C$96,config!$D$96) | Y2: =TR(tickers!$B$1202:$B$1401,config!$C$96&".date;"&config!$C$96,config!$D$96) | AC2: =TR(tickers!$B$1402:$B$1601,config!$C$96&".date;"&config!$C$96,config!$D$96)

Sheet tr_pct_2020
A1: tickers B2:B26 | E1: tickers B27:B51 | I1: tickers B52:B76 | M1: tickers B77:B101 | Q1: tickers B102:B126 | U1: tickers B127:B151 | Y1: tickers B152:B176 | AC1: tickers B177:B201 | AG1: tickers B202:B226 | AK1: tickers B227:B251 | AO1: tickers B252:B276 | AS1: tickers B277:B301 | AW1: tickers B302:B326 | BA1: tickers B327:B351 | BE1: tickers B352:B376 | BI1: tickers B377:B401 | BM1: tickers B402:B426 | BQ1: tickers B427:B451 | BU1: tickers B452:B476 | BY1: tickers B477:B501 | CC1: tickers B502:B526 | CG1: tickers B527:B551 | CK1: tickers B552:B576 | CO1: tickers B577:B601 | CS1: tickers B602:B626 | CW1: tickers B627:B651 | DA1: tickers B652:B676 | DE1: tickers B677:B701 | DI1: tickers B702:B726 | DM1: tickers B727:B751 | DQ1: tickers B752:B776 | DU1: tickers B777:B801 | DY1: tickers B802:B826 | EC1: tickers B827:B851 | EG1: tickers B852:B876 | EK1: tickers B877:B901 | EO1: tickers B902:B926 | ES1: tickers B927:B951 | EW1: tickers B952:B976 | FA1: tickers B977:B1001 | FE1: tickers B1002:B1026 | FI1: tickers B1027:B1051 | FM1: tickers B1052:B1076 | FQ1: tickers B1077:B1101 | FU1: tickers B1102:B1126 | FY1: tickers B1127:B1151 | GC1: tickers B1152:B1176 | GG1: tickers B1177:B1201 | GK1: tickers B1202:B1226 | GO1: tickers B1227:B1251 | GS1: tickers B1252:B1276 | GW1: tickers B1277:B1301 | HA1: tickers B1302:B1326 | HE1: tickers B1327:B1351 | HI1: tickers B1352:B1376 | HM1: tickers B1377:B1401 | HQ1: tickers B1402:B1426 | HU1: tickers B1427:B1451 | HY1: tickers B1452:B1476 | IC1: tickers B1477:B1501
A2: =TR(tickers!$B$2:$B$26,"TR.TotalReturn.date;TR.TotalReturn",config!$B$11) | E2: =TR(tickers!$B$27:$B$51,"TR.TotalReturn.date;TR.TotalReturn",config!$B$11) | I2: =TR(tickers!$B$52:$B$76,"TR.TotalReturn.date;TR.TotalReturn",config!$B$11) | M2: =TR(tickers!$B$77:$B$101,"TR.TotalReturn.date;TR.TotalReturn",config!$B$11) | Q2: =TR(tickers!$B$102:$B$126,"TR.TotalReturn.date;TR.TotalReturn",config!$B$11) | U2: =TR(tickers!$B$127:$B$151,"TR.TotalReturn.date;TR.TotalReturn",config!$B$11) | Y2: =TR(tickers!$B$152:$B$176,"TR.TotalReturn.date;TR.TotalReturn",config!$B$11) | AC2: =TR(tickers!$B$177:$B$201,"TR.TotalReturn.date;TR.TotalReturn",config!$B$11) | AG2: =TR(tickers!$B$202:$B$226,"TR.TotalReturn.date;TR.TotalReturn",config!$B$11) | AK2: =TR(tickers!$B$227:$B$251,"TR.TotalReturn.date;TR.TotalReturn",config!$B$11) | AO2: =TR(tickers!$B$252:$B$276,"TR.TotalReturn.date;TR.TotalReturn",config!$B$11) | AS2: =TR(tickers!$B$277:$B$301,"TR.TotalReturn.date;TR.TotalReturn",config!$B$11) | AW2: =TR(tickers!$B$302:$B$326,"TR.TotalReturn.date;TR.TotalReturn",config!$B$11) | BA2: =TR(tickers!$B$327:$B$351,"TR.TotalReturn.date;TR.TotalReturn",config!$B$11) | BE2: =TR(tickers!$B$352:$B$376,"TR.TotalReturn.date;TR.TotalReturn",config!$B$11) | BI2: =TR(tickers!$B$377:$B$401,"TR.TotalReturn.date;TR.TotalReturn",config!$B$11) | BM2: =TR(tickers!$B$402:$B$426,"TR.TotalReturn.date;TR.TotalReturn",config!$B$11) | BQ2: =TR(tickers!$B$427:$B$451,"TR.TotalReturn.date;TR.TotalReturn",config!$B$11) | BU2: =TR(tickers!$B$452:$B$476,"TR.TotalReturn.date;TR.TotalReturn",config!$B$11) | BY2: =TR(tickers!$B$477:$B$501,"TR.TotalReturn.date;TR.TotalReturn",config!$B$11) | CC2: =TR(tickers!$B$502:$B$526,"TR.TotalReturn.date;TR.TotalReturn",config!$B$11) | CG2: =TR(tickers!$B$527:$B$551,"TR.TotalReturn.date;TR.TotalReturn",config!$B$11) | CK2: =TR(tickers!$B$552:$B$576,"TR.TotalReturn.date;TR.TotalReturn",config!$B$11) | CO2: =TR(tickers!$B$577:$B$601,"TR.TotalReturn.date;TR.TotalReturn",config!$B$11) | CS2: =TR(tickers!$B$602:$B$626,"TR.TotalReturn.date;TR.TotalReturn",config!$B$11) | CW2: =TR(tickers!$B$627:$B$651,"TR.TotalReturn.date;TR.TotalReturn",config!$B$11) | DA2: =TR(tickers!$B$652:$B$676,"TR.TotalReturn.date;TR.TotalReturn",config!$B$11) | DE2: =TR(tickers!$B$677:$B$701,"TR.TotalReturn.date;TR.TotalReturn",config!$B$11) | DI2: =TR(tickers!$B$702:$B$726,"TR.TotalReturn.date;TR.TotalReturn",config!$B$11) | DM2: =TR(tickers!$B$727:$B$751,"TR.TotalReturn.date;TR.TotalReturn",config!$B$11) | DQ2: =TR(tickers!$B$752:$B$776,"TR.TotalReturn.date;TR.TotalReturn",config!$B$11) | DU2: =TR(tickers!$B$777:$B$801,"TR.TotalReturn.date;TR.TotalReturn",config!$B$11) | DY2: =TR(tickers!$B$802:$B$826,"TR.TotalReturn.date;TR.TotalReturn",config!$B$11) | EC2: =TR(tickers!$B$827:$B$851,"TR.TotalReturn.date;TR.TotalReturn",config!$B$11) | EG2: =TR(tickers!$B$852:$B$876,"TR.TotalReturn.date;TR.TotalReturn",config!$B$11) | EK2: =TR(tickers!$B$877:$B$901,"TR.TotalReturn.date;TR.TotalReturn",config!$B$11) | EO2: =TR(tickers!$B$902:$B$926,"TR.TotalReturn.date;TR.TotalReturn",config!$B$11) | ES2: =TR(tickers!$B$927:$B$951,"TR.TotalReturn.date;TR.TotalReturn",config!$B$11) | EW2: =TR(tickers!$B$952:$B$976,"TR.TotalReturn.date;TR.TotalReturn",config!$B$11) | FA2: =TR(tickers!$B$977:$B$1001,"TR.TotalReturn.date;TR.TotalReturn",config!$B$11) | FE2: =TR(tickers!$B$1002:$B$1026,"TR.TotalReturn.date;TR.TotalReturn",config!$B$11) | FI2: =TR(tickers!$B$1027:$B$1051,"TR.TotalReturn.date;TR.TotalReturn",config!$B$11) | FM2: =TR(tickers!$B$1052:$B$1076,"TR.TotalReturn.date;TR.TotalReturn",config!$B$11) | FQ2: =TR(tickers!$B$1077:$B$1101,"TR.TotalReturn.date;TR.TotalReturn",config!$B$11) | FU2: =TR(tickers!$B$1102:$B$1126,"TR.TotalReturn.date;TR.TotalReturn",config!$B$11) | FY2: =TR(tickers!$B$1127:$B$1151,"TR.TotalReturn.date;TR.TotalReturn",config!$B$11) | GC2: =TR(tickers!$B$1152:$B$1176,"TR.TotalReturn.date;TR.TotalReturn",config!$B$11) | GG2: =TR(tickers!$B$1177:$B$1201,"TR.TotalReturn.date;TR.TotalReturn",config!$B$11) | GK2: =TR(tickers!$B$1202:$B$1226,"TR.TotalReturn.date;TR.TotalReturn",config!$B$11) | GO2: =TR(tickers!$B$1227:$B$1251,"TR.TotalReturn.date;TR.TotalReturn",config!$B$11) | GS2: =TR(tickers!$B$1252:$B$1276,"TR.TotalReturn.date;TR.TotalReturn",config!$B$11) | GW2: =TR(tickers!$B$1277:$B$1301,"TR.TotalReturn.date;TR.TotalReturn",config!$B$11) | HA2: =TR(tickers!$B$1302:$B$1326,"TR.TotalReturn.date;TR.TotalReturn",config!$B$11) | HE2: =TR(tickers!$B$1327:$B$1351,"TR.TotalReturn.date;TR.TotalReturn",config!$B$11) | HI2: =TR(tickers!$B$1352:$B$1376,"TR.TotalReturn.date;TR.TotalReturn",config!$B$11) | HM2: =TR(tickers!$B$1377:$B$1401,"TR.TotalReturn.date;TR.TotalReturn",config!$B$11) | HQ2: =TR(tickers!$B$1402:$B$1426,"TR.TotalReturn.date;TR.TotalReturn",config!$B$11) | HU2: =TR(tickers!$B$1427:$B$1451,"TR.TotalReturn.date;TR.TotalReturn",config!$B$11) | HY2: =TR(tickers!$B$1452:$B$1476,"TR.TotalReturn.date;TR.TotalReturn",config!$B$11) | IC2: =TR(tickers!$B$1477:$B$1501,"TR.TotalReturn.date;TR.TotalReturn",config!$B$11)

Sheet px_last_2020
A1: tickers B2:B26 | E1: tickers B27:B51 | I1: tickers B52:B76 | M1: tickers B77:B101 | Q1: tickers B102:B126 | U1: tickers B127:B151 | Y1: tickers B152:B176 | AC1: tickers B177:B201 | AG1: tickers B202:B226 | AK1: tickers B227:B251 | AO1: tickers B252:B276 | AS1: tickers B277:B301 | AW1: tickers B302:B326 | BA1: tickers B327:B351 | BE1: tickers B352:B376 | BI1: tickers B377:B401 | BM1: tickers B402:B426 | BQ1: tickers B427:B451 | BU1: tickers B452:B476 | BY1: tickers B477:B501 | CC1: tickers B502:B526 | CG1: tickers B527:B551 | CK1: tickers B552:B576 | CO1: tickers B577:B601 | CS1: tickers B602:B626 | CW1: tickers B627:B651 | DA1: tickers B652:B676 | DE1: tickers B677:B701 | DI1: tickers B702:B726 | DM1: tickers B727:B751 | DQ1: tickers B752:B776 | DU1: tickers B777:B801 | DY1: tickers B802:B826 | EC1: tickers B827:B851 | EG1: tickers B852:B876 | EK1: tickers B877:B901 | EO1: tickers B902:B926 | ES1: tickers B927:B951 | EW1: tickers B952:B976 | FA1: tickers B977:B1001 | FE1: tickers B1002:B1026 | FI1: tickers B1027:B1051 | FM1: tickers B1052:B1076 | FQ1: tickers B1077:B1101 | FU1: tickers B1102:B1126 | FY1: tickers B1127:B1151 | GC1: tickers B1152:B1176 | GG1: tickers B1177:B1201 | GK1: tickers B1202:B1226 | GO1: tickers B1227:B1251 | GS1: tickers B1252:B1276 | GW1: tickers B1277:B1301 | HA1: tickers B1302:B1326 | HE1: tickers B1327:B1351 | HI1: tickers B1352:B1376 | HM1: tickers B1377:B1401 | HQ1: tickers B1402:B1426 | HU1: tickers B1427:B1451 | HY1: tickers B1452:B1476 | IC1: tickers B1477:B1501
